{
 "cells": [
  {
   "cell_type": "code",
   "execution_count": 3,
   "metadata": {},
   "outputs": [
    {
     "name": "stderr",
     "output_type": "stream",
     "text": [
      "\n",
      "A module that was compiled using NumPy 1.x cannot be run in\n",
      "NumPy 2.0.2 as it may crash. To support both 1.x and 2.x\n",
      "versions of NumPy, modules must be compiled with NumPy 2.0.\n",
      "Some module may need to rebuild instead e.g. with 'pybind11>=2.12'.\n",
      "\n",
      "If you are a user of the module, the easiest solution will be to\n",
      "downgrade to 'numpy<2' or try to upgrade the affected module.\n",
      "We expect that some modules will need time to support NumPy 2.\n",
      "\n",
      "Traceback (most recent call last):  File \"<frozen runpy>\", line 198, in _run_module_as_main\n",
      "  File \"<frozen runpy>\", line 88, in _run_code\n",
      "  File \"/opt/anaconda3/lib/python3.12/site-packages/ipykernel_launcher.py\", line 17, in <module>\n",
      "    app.launch_new_instance()\n",
      "  File \"/opt/anaconda3/lib/python3.12/site-packages/traitlets/config/application.py\", line 1075, in launch_instance\n",
      "    app.start()\n",
      "  File \"/opt/anaconda3/lib/python3.12/site-packages/ipykernel/kernelapp.py\", line 701, in start\n",
      "    self.io_loop.start()\n",
      "  File \"/opt/anaconda3/lib/python3.12/site-packages/tornado/platform/asyncio.py\", line 205, in start\n",
      "    self.asyncio_loop.run_forever()\n",
      "  File \"/opt/anaconda3/lib/python3.12/asyncio/base_events.py\", line 639, in run_forever\n",
      "    self._run_once()\n",
      "  File \"/opt/anaconda3/lib/python3.12/asyncio/base_events.py\", line 1985, in _run_once\n",
      "    handle._run()\n",
      "  File \"/opt/anaconda3/lib/python3.12/asyncio/events.py\", line 88, in _run\n",
      "    self._context.run(self._callback, *self._args)\n",
      "  File \"/opt/anaconda3/lib/python3.12/site-packages/ipykernel/kernelbase.py\", line 534, in dispatch_queue\n",
      "    await self.process_one()\n",
      "  File \"/opt/anaconda3/lib/python3.12/site-packages/ipykernel/kernelbase.py\", line 523, in process_one\n",
      "    await dispatch(*args)\n",
      "  File \"/opt/anaconda3/lib/python3.12/site-packages/ipykernel/kernelbase.py\", line 429, in dispatch_shell\n",
      "    await result\n",
      "  File \"/opt/anaconda3/lib/python3.12/site-packages/ipykernel/kernelbase.py\", line 767, in execute_request\n",
      "    reply_content = await reply_content\n",
      "  File \"/opt/anaconda3/lib/python3.12/site-packages/ipykernel/ipkernel.py\", line 429, in do_execute\n",
      "    res = shell.run_cell(\n",
      "  File \"/opt/anaconda3/lib/python3.12/site-packages/ipykernel/zmqshell.py\", line 549, in run_cell\n",
      "    return super().run_cell(*args, **kwargs)\n",
      "  File \"/opt/anaconda3/lib/python3.12/site-packages/IPython/core/interactiveshell.py\", line 3075, in run_cell\n",
      "    result = self._run_cell(\n",
      "  File \"/opt/anaconda3/lib/python3.12/site-packages/IPython/core/interactiveshell.py\", line 3130, in _run_cell\n",
      "    result = runner(coro)\n",
      "  File \"/opt/anaconda3/lib/python3.12/site-packages/IPython/core/async_helpers.py\", line 129, in _pseudo_sync_runner\n",
      "    coro.send(None)\n",
      "  File \"/opt/anaconda3/lib/python3.12/site-packages/IPython/core/interactiveshell.py\", line 3334, in run_cell_async\n",
      "    has_raised = await self.run_ast_nodes(code_ast.body, cell_name,\n",
      "  File \"/opt/anaconda3/lib/python3.12/site-packages/IPython/core/interactiveshell.py\", line 3517, in run_ast_nodes\n",
      "    if await self.run_code(code, result, async_=asy):\n",
      "  File \"/opt/anaconda3/lib/python3.12/site-packages/IPython/core/interactiveshell.py\", line 3577, in run_code\n",
      "    exec(code_obj, self.user_global_ns, self.user_ns)\n",
      "  File \"/var/folders/j4/01bw0t0n5195l3682d9brqz40000gn/T/ipykernel_20082/4080736814.py\", line 1, in <module>\n",
      "    import pandas as pd\n",
      "  File \"/opt/anaconda3/lib/python3.12/site-packages/pandas/__init__.py\", line 26, in <module>\n",
      "    from pandas.compat import (\n",
      "  File \"/opt/anaconda3/lib/python3.12/site-packages/pandas/compat/__init__.py\", line 27, in <module>\n",
      "    from pandas.compat.pyarrow import (\n",
      "  File \"/opt/anaconda3/lib/python3.12/site-packages/pandas/compat/pyarrow.py\", line 8, in <module>\n",
      "    import pyarrow as pa\n",
      "  File \"/opt/anaconda3/lib/python3.12/site-packages/pyarrow/__init__.py\", line 65, in <module>\n",
      "    import pyarrow.lib as _lib\n"
     ]
    },
    {
     "ename": "ImportError",
     "evalue": "\nA module that was compiled using NumPy 1.x cannot be run in\nNumPy 2.0.2 as it may crash. To support both 1.x and 2.x\nversions of NumPy, modules must be compiled with NumPy 2.0.\nSome module may need to rebuild instead e.g. with 'pybind11>=2.12'.\n\nIf you are a user of the module, the easiest solution will be to\ndowngrade to 'numpy<2' or try to upgrade the affected module.\nWe expect that some modules will need time to support NumPy 2.\n\n",
     "output_type": "error",
     "traceback": [
      "\u001b[0;31m---------------------------------------------------------------------------\u001b[0m",
      "\u001b[0;31mImportError\u001b[0m                               Traceback (most recent call last)",
      "File \u001b[0;32m/opt/anaconda3/lib/python3.12/site-packages/numpy/core/_multiarray_umath.py:44\u001b[0m, in \u001b[0;36m__getattr__\u001b[0;34m(attr_name)\u001b[0m\n\u001b[1;32m     39\u001b[0m     \u001b[38;5;66;03m# Also print the message (with traceback).  This is because old versions\u001b[39;00m\n\u001b[1;32m     40\u001b[0m     \u001b[38;5;66;03m# of NumPy unfortunately set up the import to replace (and hide) the\u001b[39;00m\n\u001b[1;32m     41\u001b[0m     \u001b[38;5;66;03m# error.  The traceback shouldn't be needed, but e.g. pytest plugins\u001b[39;00m\n\u001b[1;32m     42\u001b[0m     \u001b[38;5;66;03m# seem to swallow it and we should be failing anyway...\u001b[39;00m\n\u001b[1;32m     43\u001b[0m     sys\u001b[38;5;241m.\u001b[39mstderr\u001b[38;5;241m.\u001b[39mwrite(msg \u001b[38;5;241m+\u001b[39m tb_msg)\n\u001b[0;32m---> 44\u001b[0m     \u001b[38;5;28;01mraise\u001b[39;00m \u001b[38;5;167;01mImportError\u001b[39;00m(msg)\n\u001b[1;32m     46\u001b[0m ret \u001b[38;5;241m=\u001b[39m \u001b[38;5;28mgetattr\u001b[39m(_multiarray_umath, attr_name, \u001b[38;5;28;01mNone\u001b[39;00m)\n\u001b[1;32m     47\u001b[0m \u001b[38;5;28;01mif\u001b[39;00m ret \u001b[38;5;129;01mis\u001b[39;00m \u001b[38;5;28;01mNone\u001b[39;00m:\n",
      "\u001b[0;31mImportError\u001b[0m: \nA module that was compiled using NumPy 1.x cannot be run in\nNumPy 2.0.2 as it may crash. To support both 1.x and 2.x\nversions of NumPy, modules must be compiled with NumPy 2.0.\nSome module may need to rebuild instead e.g. with 'pybind11>=2.12'.\n\nIf you are a user of the module, the easiest solution will be to\ndowngrade to 'numpy<2' or try to upgrade the affected module.\nWe expect that some modules will need time to support NumPy 2.\n\n"
     ]
    },
    {
     "name": "stderr",
     "output_type": "stream",
     "text": [
      "\n",
      "A module that was compiled using NumPy 1.x cannot be run in\n",
      "NumPy 2.0.2 as it may crash. To support both 1.x and 2.x\n",
      "versions of NumPy, modules must be compiled with NumPy 2.0.\n",
      "Some module may need to rebuild instead e.g. with 'pybind11>=2.12'.\n",
      "\n",
      "If you are a user of the module, the easiest solution will be to\n",
      "downgrade to 'numpy<2' or try to upgrade the affected module.\n",
      "We expect that some modules will need time to support NumPy 2.\n",
      "\n",
      "Traceback (most recent call last):  File \"<frozen runpy>\", line 198, in _run_module_as_main\n",
      "  File \"<frozen runpy>\", line 88, in _run_code\n",
      "  File \"/opt/anaconda3/lib/python3.12/site-packages/ipykernel_launcher.py\", line 17, in <module>\n",
      "    app.launch_new_instance()\n",
      "  File \"/opt/anaconda3/lib/python3.12/site-packages/traitlets/config/application.py\", line 1075, in launch_instance\n",
      "    app.start()\n",
      "  File \"/opt/anaconda3/lib/python3.12/site-packages/ipykernel/kernelapp.py\", line 701, in start\n",
      "    self.io_loop.start()\n",
      "  File \"/opt/anaconda3/lib/python3.12/site-packages/tornado/platform/asyncio.py\", line 205, in start\n",
      "    self.asyncio_loop.run_forever()\n",
      "  File \"/opt/anaconda3/lib/python3.12/asyncio/base_events.py\", line 639, in run_forever\n",
      "    self._run_once()\n",
      "  File \"/opt/anaconda3/lib/python3.12/asyncio/base_events.py\", line 1985, in _run_once\n",
      "    handle._run()\n",
      "  File \"/opt/anaconda3/lib/python3.12/asyncio/events.py\", line 88, in _run\n",
      "    self._context.run(self._callback, *self._args)\n",
      "  File \"/opt/anaconda3/lib/python3.12/site-packages/ipykernel/kernelbase.py\", line 534, in dispatch_queue\n",
      "    await self.process_one()\n",
      "  File \"/opt/anaconda3/lib/python3.12/site-packages/ipykernel/kernelbase.py\", line 523, in process_one\n",
      "    await dispatch(*args)\n",
      "  File \"/opt/anaconda3/lib/python3.12/site-packages/ipykernel/kernelbase.py\", line 429, in dispatch_shell\n",
      "    await result\n",
      "  File \"/opt/anaconda3/lib/python3.12/site-packages/ipykernel/kernelbase.py\", line 767, in execute_request\n",
      "    reply_content = await reply_content\n",
      "  File \"/opt/anaconda3/lib/python3.12/site-packages/ipykernel/ipkernel.py\", line 429, in do_execute\n",
      "    res = shell.run_cell(\n",
      "  File \"/opt/anaconda3/lib/python3.12/site-packages/ipykernel/zmqshell.py\", line 549, in run_cell\n",
      "    return super().run_cell(*args, **kwargs)\n",
      "  File \"/opt/anaconda3/lib/python3.12/site-packages/IPython/core/interactiveshell.py\", line 3075, in run_cell\n",
      "    result = self._run_cell(\n",
      "  File \"/opt/anaconda3/lib/python3.12/site-packages/IPython/core/interactiveshell.py\", line 3130, in _run_cell\n",
      "    result = runner(coro)\n",
      "  File \"/opt/anaconda3/lib/python3.12/site-packages/IPython/core/async_helpers.py\", line 129, in _pseudo_sync_runner\n",
      "    coro.send(None)\n",
      "  File \"/opt/anaconda3/lib/python3.12/site-packages/IPython/core/interactiveshell.py\", line 3334, in run_cell_async\n",
      "    has_raised = await self.run_ast_nodes(code_ast.body, cell_name,\n",
      "  File \"/opt/anaconda3/lib/python3.12/site-packages/IPython/core/interactiveshell.py\", line 3517, in run_ast_nodes\n",
      "    if await self.run_code(code, result, async_=asy):\n",
      "  File \"/opt/anaconda3/lib/python3.12/site-packages/IPython/core/interactiveshell.py\", line 3577, in run_code\n",
      "    exec(code_obj, self.user_global_ns, self.user_ns)\n",
      "  File \"/var/folders/j4/01bw0t0n5195l3682d9brqz40000gn/T/ipykernel_20082/4080736814.py\", line 1, in <module>\n",
      "    import pandas as pd\n",
      "  File \"/opt/anaconda3/lib/python3.12/site-packages/pandas/__init__.py\", line 49, in <module>\n",
      "    from pandas.core.api import (\n",
      "  File \"/opt/anaconda3/lib/python3.12/site-packages/pandas/core/api.py\", line 9, in <module>\n",
      "    from pandas.core.dtypes.dtypes import (\n",
      "  File \"/opt/anaconda3/lib/python3.12/site-packages/pandas/core/dtypes/dtypes.py\", line 24, in <module>\n",
      "    from pandas._libs import (\n",
      "  File \"/opt/anaconda3/lib/python3.12/site-packages/pyarrow/__init__.py\", line 65, in <module>\n",
      "    import pyarrow.lib as _lib\n"
     ]
    },
    {
     "ename": "ImportError",
     "evalue": "\nA module that was compiled using NumPy 1.x cannot be run in\nNumPy 2.0.2 as it may crash. To support both 1.x and 2.x\nversions of NumPy, modules must be compiled with NumPy 2.0.\nSome module may need to rebuild instead e.g. with 'pybind11>=2.12'.\n\nIf you are a user of the module, the easiest solution will be to\ndowngrade to 'numpy<2' or try to upgrade the affected module.\nWe expect that some modules will need time to support NumPy 2.\n\n",
     "output_type": "error",
     "traceback": [
      "\u001b[0;31m---------------------------------------------------------------------------\u001b[0m",
      "\u001b[0;31mImportError\u001b[0m                               Traceback (most recent call last)",
      "File \u001b[0;32m/opt/anaconda3/lib/python3.12/site-packages/numpy/core/_multiarray_umath.py:44\u001b[0m, in \u001b[0;36m__getattr__\u001b[0;34m(attr_name)\u001b[0m\n\u001b[1;32m     39\u001b[0m     \u001b[38;5;66;03m# Also print the message (with traceback).  This is because old versions\u001b[39;00m\n\u001b[1;32m     40\u001b[0m     \u001b[38;5;66;03m# of NumPy unfortunately set up the import to replace (and hide) the\u001b[39;00m\n\u001b[1;32m     41\u001b[0m     \u001b[38;5;66;03m# error.  The traceback shouldn't be needed, but e.g. pytest plugins\u001b[39;00m\n\u001b[1;32m     42\u001b[0m     \u001b[38;5;66;03m# seem to swallow it and we should be failing anyway...\u001b[39;00m\n\u001b[1;32m     43\u001b[0m     sys\u001b[38;5;241m.\u001b[39mstderr\u001b[38;5;241m.\u001b[39mwrite(msg \u001b[38;5;241m+\u001b[39m tb_msg)\n\u001b[0;32m---> 44\u001b[0m     \u001b[38;5;28;01mraise\u001b[39;00m \u001b[38;5;167;01mImportError\u001b[39;00m(msg)\n\u001b[1;32m     46\u001b[0m ret \u001b[38;5;241m=\u001b[39m \u001b[38;5;28mgetattr\u001b[39m(_multiarray_umath, attr_name, \u001b[38;5;28;01mNone\u001b[39;00m)\n\u001b[1;32m     47\u001b[0m \u001b[38;5;28;01mif\u001b[39;00m ret \u001b[38;5;129;01mis\u001b[39;00m \u001b[38;5;28;01mNone\u001b[39;00m:\n",
      "\u001b[0;31mImportError\u001b[0m: \nA module that was compiled using NumPy 1.x cannot be run in\nNumPy 2.0.2 as it may crash. To support both 1.x and 2.x\nversions of NumPy, modules must be compiled with NumPy 2.0.\nSome module may need to rebuild instead e.g. with 'pybind11>=2.12'.\n\nIf you are a user of the module, the easiest solution will be to\ndowngrade to 'numpy<2' or try to upgrade the affected module.\nWe expect that some modules will need time to support NumPy 2.\n\n"
     ]
    },
    {
     "name": "stderr",
     "output_type": "stream",
     "text": [
      "\n",
      "A module that was compiled using NumPy 1.x cannot be run in\n",
      "NumPy 2.0.2 as it may crash. To support both 1.x and 2.x\n",
      "versions of NumPy, modules must be compiled with NumPy 2.0.\n",
      "Some module may need to rebuild instead e.g. with 'pybind11>=2.12'.\n",
      "\n",
      "If you are a user of the module, the easiest solution will be to\n",
      "downgrade to 'numpy<2' or try to upgrade the affected module.\n",
      "We expect that some modules will need time to support NumPy 2.\n",
      "\n",
      "Traceback (most recent call last):  File \"<frozen runpy>\", line 198, in _run_module_as_main\n",
      "  File \"<frozen runpy>\", line 88, in _run_code\n",
      "  File \"/opt/anaconda3/lib/python3.12/site-packages/ipykernel_launcher.py\", line 17, in <module>\n",
      "    app.launch_new_instance()\n",
      "  File \"/opt/anaconda3/lib/python3.12/site-packages/traitlets/config/application.py\", line 1075, in launch_instance\n",
      "    app.start()\n",
      "  File \"/opt/anaconda3/lib/python3.12/site-packages/ipykernel/kernelapp.py\", line 701, in start\n",
      "    self.io_loop.start()\n",
      "  File \"/opt/anaconda3/lib/python3.12/site-packages/tornado/platform/asyncio.py\", line 205, in start\n",
      "    self.asyncio_loop.run_forever()\n",
      "  File \"/opt/anaconda3/lib/python3.12/asyncio/base_events.py\", line 639, in run_forever\n",
      "    self._run_once()\n",
      "  File \"/opt/anaconda3/lib/python3.12/asyncio/base_events.py\", line 1985, in _run_once\n",
      "    handle._run()\n",
      "  File \"/opt/anaconda3/lib/python3.12/asyncio/events.py\", line 88, in _run\n",
      "    self._context.run(self._callback, *self._args)\n",
      "  File \"/opt/anaconda3/lib/python3.12/site-packages/ipykernel/kernelbase.py\", line 534, in dispatch_queue\n",
      "    await self.process_one()\n",
      "  File \"/opt/anaconda3/lib/python3.12/site-packages/ipykernel/kernelbase.py\", line 523, in process_one\n",
      "    await dispatch(*args)\n",
      "  File \"/opt/anaconda3/lib/python3.12/site-packages/ipykernel/kernelbase.py\", line 429, in dispatch_shell\n",
      "    await result\n",
      "  File \"/opt/anaconda3/lib/python3.12/site-packages/ipykernel/kernelbase.py\", line 767, in execute_request\n",
      "    reply_content = await reply_content\n",
      "  File \"/opt/anaconda3/lib/python3.12/site-packages/ipykernel/ipkernel.py\", line 429, in do_execute\n",
      "    res = shell.run_cell(\n",
      "  File \"/opt/anaconda3/lib/python3.12/site-packages/ipykernel/zmqshell.py\", line 549, in run_cell\n",
      "    return super().run_cell(*args, **kwargs)\n",
      "  File \"/opt/anaconda3/lib/python3.12/site-packages/IPython/core/interactiveshell.py\", line 3075, in run_cell\n",
      "    result = self._run_cell(\n",
      "  File \"/opt/anaconda3/lib/python3.12/site-packages/IPython/core/interactiveshell.py\", line 3130, in _run_cell\n",
      "    result = runner(coro)\n",
      "  File \"/opt/anaconda3/lib/python3.12/site-packages/IPython/core/async_helpers.py\", line 129, in _pseudo_sync_runner\n",
      "    coro.send(None)\n",
      "  File \"/opt/anaconda3/lib/python3.12/site-packages/IPython/core/interactiveshell.py\", line 3334, in run_cell_async\n",
      "    has_raised = await self.run_ast_nodes(code_ast.body, cell_name,\n",
      "  File \"/opt/anaconda3/lib/python3.12/site-packages/IPython/core/interactiveshell.py\", line 3517, in run_ast_nodes\n",
      "    if await self.run_code(code, result, async_=asy):\n",
      "  File \"/opt/anaconda3/lib/python3.12/site-packages/IPython/core/interactiveshell.py\", line 3577, in run_code\n",
      "    exec(code_obj, self.user_global_ns, self.user_ns)\n",
      "  File \"/var/folders/j4/01bw0t0n5195l3682d9brqz40000gn/T/ipykernel_20082/4080736814.py\", line 1, in <module>\n",
      "    import pandas as pd\n",
      "  File \"/opt/anaconda3/lib/python3.12/site-packages/pandas/__init__.py\", line 49, in <module>\n",
      "    from pandas.core.api import (\n",
      "  File \"/opt/anaconda3/lib/python3.12/site-packages/pandas/core/api.py\", line 28, in <module>\n",
      "    from pandas.core.arrays import Categorical\n",
      "  File \"/opt/anaconda3/lib/python3.12/site-packages/pandas/core/arrays/__init__.py\", line 1, in <module>\n",
      "    from pandas.core.arrays.arrow import ArrowExtensionArray\n",
      "  File \"/opt/anaconda3/lib/python3.12/site-packages/pandas/core/arrays/arrow/__init__.py\", line 5, in <module>\n",
      "    from pandas.core.arrays.arrow.array import ArrowExtensionArray\n",
      "  File \"/opt/anaconda3/lib/python3.12/site-packages/pandas/core/arrays/arrow/array.py\", line 50, in <module>\n",
      "    from pandas.core import (\n",
      "  File \"/opt/anaconda3/lib/python3.12/site-packages/pandas/core/ops/__init__.py\", line 8, in <module>\n",
      "    from pandas.core.ops.array_ops import (\n",
      "  File \"/opt/anaconda3/lib/python3.12/site-packages/pandas/core/ops/array_ops.py\", line 56, in <module>\n",
      "    from pandas.core.computation import expressions\n",
      "  File \"/opt/anaconda3/lib/python3.12/site-packages/pandas/core/computation/expressions.py\", line 21, in <module>\n",
      "    from pandas.core.computation.check import NUMEXPR_INSTALLED\n",
      "  File \"/opt/anaconda3/lib/python3.12/site-packages/pandas/core/computation/check.py\", line 5, in <module>\n",
      "    ne = import_optional_dependency(\"numexpr\", errors=\"warn\")\n",
      "  File \"/opt/anaconda3/lib/python3.12/site-packages/pandas/compat/_optional.py\", line 135, in import_optional_dependency\n",
      "    module = importlib.import_module(name)\n",
      "  File \"/opt/anaconda3/lib/python3.12/importlib/__init__.py\", line 90, in import_module\n",
      "    return _bootstrap._gcd_import(name[level:], package, level)\n",
      "  File \"/opt/anaconda3/lib/python3.12/site-packages/numexpr/__init__.py\", line 24, in <module>\n",
      "    from numexpr.interpreter import MAX_THREADS, use_vml, __BLOCK_SIZE1__\n"
     ]
    },
    {
     "ename": "AttributeError",
     "evalue": "_ARRAY_API not found",
     "output_type": "error",
     "traceback": [
      "\u001b[0;31m---------------------------------------------------------------------------\u001b[0m",
      "\u001b[0;31mAttributeError\u001b[0m                            Traceback (most recent call last)",
      "\u001b[0;31mAttributeError\u001b[0m: _ARRAY_API not found"
     ]
    },
    {
     "name": "stderr",
     "output_type": "stream",
     "text": [
      "\n",
      "A module that was compiled using NumPy 1.x cannot be run in\n",
      "NumPy 2.0.2 as it may crash. To support both 1.x and 2.x\n",
      "versions of NumPy, modules must be compiled with NumPy 2.0.\n",
      "Some module may need to rebuild instead e.g. with 'pybind11>=2.12'.\n",
      "\n",
      "If you are a user of the module, the easiest solution will be to\n",
      "downgrade to 'numpy<2' or try to upgrade the affected module.\n",
      "We expect that some modules will need time to support NumPy 2.\n",
      "\n",
      "Traceback (most recent call last):  File \"<frozen runpy>\", line 198, in _run_module_as_main\n",
      "  File \"<frozen runpy>\", line 88, in _run_code\n",
      "  File \"/opt/anaconda3/lib/python3.12/site-packages/ipykernel_launcher.py\", line 17, in <module>\n",
      "    app.launch_new_instance()\n",
      "  File \"/opt/anaconda3/lib/python3.12/site-packages/traitlets/config/application.py\", line 1075, in launch_instance\n",
      "    app.start()\n",
      "  File \"/opt/anaconda3/lib/python3.12/site-packages/ipykernel/kernelapp.py\", line 701, in start\n",
      "    self.io_loop.start()\n",
      "  File \"/opt/anaconda3/lib/python3.12/site-packages/tornado/platform/asyncio.py\", line 205, in start\n",
      "    self.asyncio_loop.run_forever()\n",
      "  File \"/opt/anaconda3/lib/python3.12/asyncio/base_events.py\", line 639, in run_forever\n",
      "    self._run_once()\n",
      "  File \"/opt/anaconda3/lib/python3.12/asyncio/base_events.py\", line 1985, in _run_once\n",
      "    handle._run()\n",
      "  File \"/opt/anaconda3/lib/python3.12/asyncio/events.py\", line 88, in _run\n",
      "    self._context.run(self._callback, *self._args)\n",
      "  File \"/opt/anaconda3/lib/python3.12/site-packages/ipykernel/kernelbase.py\", line 534, in dispatch_queue\n",
      "    await self.process_one()\n",
      "  File \"/opt/anaconda3/lib/python3.12/site-packages/ipykernel/kernelbase.py\", line 523, in process_one\n",
      "    await dispatch(*args)\n",
      "  File \"/opt/anaconda3/lib/python3.12/site-packages/ipykernel/kernelbase.py\", line 429, in dispatch_shell\n",
      "    await result\n",
      "  File \"/opt/anaconda3/lib/python3.12/site-packages/ipykernel/kernelbase.py\", line 767, in execute_request\n",
      "    reply_content = await reply_content\n",
      "  File \"/opt/anaconda3/lib/python3.12/site-packages/ipykernel/ipkernel.py\", line 429, in do_execute\n",
      "    res = shell.run_cell(\n",
      "  File \"/opt/anaconda3/lib/python3.12/site-packages/ipykernel/zmqshell.py\", line 549, in run_cell\n",
      "    return super().run_cell(*args, **kwargs)\n",
      "  File \"/opt/anaconda3/lib/python3.12/site-packages/IPython/core/interactiveshell.py\", line 3075, in run_cell\n",
      "    result = self._run_cell(\n",
      "  File \"/opt/anaconda3/lib/python3.12/site-packages/IPython/core/interactiveshell.py\", line 3130, in _run_cell\n",
      "    result = runner(coro)\n",
      "  File \"/opt/anaconda3/lib/python3.12/site-packages/IPython/core/async_helpers.py\", line 129, in _pseudo_sync_runner\n",
      "    coro.send(None)\n",
      "  File \"/opt/anaconda3/lib/python3.12/site-packages/IPython/core/interactiveshell.py\", line 3334, in run_cell_async\n",
      "    has_raised = await self.run_ast_nodes(code_ast.body, cell_name,\n",
      "  File \"/opt/anaconda3/lib/python3.12/site-packages/IPython/core/interactiveshell.py\", line 3517, in run_ast_nodes\n",
      "    if await self.run_code(code, result, async_=asy):\n",
      "  File \"/opt/anaconda3/lib/python3.12/site-packages/IPython/core/interactiveshell.py\", line 3577, in run_code\n",
      "    exec(code_obj, self.user_global_ns, self.user_ns)\n",
      "  File \"/var/folders/j4/01bw0t0n5195l3682d9brqz40000gn/T/ipykernel_20082/4080736814.py\", line 1, in <module>\n",
      "    import pandas as pd\n",
      "  File \"/opt/anaconda3/lib/python3.12/site-packages/pandas/__init__.py\", line 49, in <module>\n",
      "    from pandas.core.api import (\n",
      "  File \"/opt/anaconda3/lib/python3.12/site-packages/pandas/core/api.py\", line 28, in <module>\n",
      "    from pandas.core.arrays import Categorical\n",
      "  File \"/opt/anaconda3/lib/python3.12/site-packages/pandas/core/arrays/__init__.py\", line 1, in <module>\n",
      "    from pandas.core.arrays.arrow import ArrowExtensionArray\n",
      "  File \"/opt/anaconda3/lib/python3.12/site-packages/pandas/core/arrays/arrow/__init__.py\", line 5, in <module>\n",
      "    from pandas.core.arrays.arrow.array import ArrowExtensionArray\n",
      "  File \"/opt/anaconda3/lib/python3.12/site-packages/pandas/core/arrays/arrow/array.py\", line 64, in <module>\n",
      "    from pandas.core.arrays.masked import BaseMaskedArray\n",
      "  File \"/opt/anaconda3/lib/python3.12/site-packages/pandas/core/arrays/masked.py\", line 60, in <module>\n",
      "    from pandas.core import (\n",
      "  File \"/opt/anaconda3/lib/python3.12/site-packages/pandas/core/nanops.py\", line 52, in <module>\n",
      "    bn = import_optional_dependency(\"bottleneck\", errors=\"warn\")\n",
      "  File \"/opt/anaconda3/lib/python3.12/site-packages/pandas/compat/_optional.py\", line 135, in import_optional_dependency\n",
      "    module = importlib.import_module(name)\n",
      "  File \"/opt/anaconda3/lib/python3.12/importlib/__init__.py\", line 90, in import_module\n",
      "    return _bootstrap._gcd_import(name[level:], package, level)\n",
      "  File \"/opt/anaconda3/lib/python3.12/site-packages/bottleneck/__init__.py\", line 7, in <module>\n",
      "    from .move import (move_argmax, move_argmin, move_max, move_mean, move_median,\n"
     ]
    },
    {
     "ename": "ImportError",
     "evalue": "\nA module that was compiled using NumPy 1.x cannot be run in\nNumPy 2.0.2 as it may crash. To support both 1.x and 2.x\nversions of NumPy, modules must be compiled with NumPy 2.0.\nSome module may need to rebuild instead e.g. with 'pybind11>=2.12'.\n\nIf you are a user of the module, the easiest solution will be to\ndowngrade to 'numpy<2' or try to upgrade the affected module.\nWe expect that some modules will need time to support NumPy 2.\n\n",
     "output_type": "error",
     "traceback": [
      "\u001b[0;31m---------------------------------------------------------------------------\u001b[0m",
      "\u001b[0;31mImportError\u001b[0m                               Traceback (most recent call last)",
      "File \u001b[0;32m/opt/anaconda3/lib/python3.12/site-packages/numpy/core/_multiarray_umath.py:44\u001b[0m, in \u001b[0;36m__getattr__\u001b[0;34m(attr_name)\u001b[0m\n\u001b[1;32m     39\u001b[0m     \u001b[38;5;66;03m# Also print the message (with traceback).  This is because old versions\u001b[39;00m\n\u001b[1;32m     40\u001b[0m     \u001b[38;5;66;03m# of NumPy unfortunately set up the import to replace (and hide) the\u001b[39;00m\n\u001b[1;32m     41\u001b[0m     \u001b[38;5;66;03m# error.  The traceback shouldn't be needed, but e.g. pytest plugins\u001b[39;00m\n\u001b[1;32m     42\u001b[0m     \u001b[38;5;66;03m# seem to swallow it and we should be failing anyway...\u001b[39;00m\n\u001b[1;32m     43\u001b[0m     sys\u001b[38;5;241m.\u001b[39mstderr\u001b[38;5;241m.\u001b[39mwrite(msg \u001b[38;5;241m+\u001b[39m tb_msg)\n\u001b[0;32m---> 44\u001b[0m     \u001b[38;5;28;01mraise\u001b[39;00m \u001b[38;5;167;01mImportError\u001b[39;00m(msg)\n\u001b[1;32m     46\u001b[0m ret \u001b[38;5;241m=\u001b[39m \u001b[38;5;28mgetattr\u001b[39m(_multiarray_umath, attr_name, \u001b[38;5;28;01mNone\u001b[39;00m)\n\u001b[1;32m     47\u001b[0m \u001b[38;5;28;01mif\u001b[39;00m ret \u001b[38;5;129;01mis\u001b[39;00m \u001b[38;5;28;01mNone\u001b[39;00m:\n",
      "\u001b[0;31mImportError\u001b[0m: \nA module that was compiled using NumPy 1.x cannot be run in\nNumPy 2.0.2 as it may crash. To support both 1.x and 2.x\nversions of NumPy, modules must be compiled with NumPy 2.0.\nSome module may need to rebuild instead e.g. with 'pybind11>=2.12'.\n\nIf you are a user of the module, the easiest solution will be to\ndowngrade to 'numpy<2' or try to upgrade the affected module.\nWe expect that some modules will need time to support NumPy 2.\n\n"
     ]
    }
   ],
   "source": [
    "import pandas as pd"
   ]
  },
  {
   "cell_type": "code",
   "execution_count": 4,
   "metadata": {},
   "outputs": [],
   "source": [
    "# Input File\n",
    "inputfile = 'CDE.bagofwords.csv'\n",
    "\n",
    "# Output File\n",
    "outputfile = 'CDE.bagofwords.csv'"
   ]
  },
  {
   "cell_type": "code",
   "execution_count": 5,
   "metadata": {},
   "outputs": [],
   "source": [
    "# Calculate Evaluation Score Function\n",
    "def evaluation(cosine_sim, sentiment):\n",
    "    try:\n",
    "        norm_sentiment = (float(sentiment) + 1) / 2\n",
    "        return ((cosine_sim * 0.8) + (norm_sentiment * 0.2))\n",
    "    except Exception as e:\n",
    "        return(0)"
   ]
  },
  {
   "cell_type": "code",
   "execution_count": 6,
   "metadata": {},
   "outputs": [],
   "source": [
    "# Import Data\n",
    "data = pd.read_csv(inputfile)\n",
    "cosine_sim = data['Cosine Similarity TFIDF']\n",
    "sentiment = data['Sentiment Scores']"
   ]
  },
  {
   "cell_type": "code",
   "execution_count": 8,
   "metadata": {},
   "outputs": [],
   "source": [
    "data = data.drop(data.columns[0:3], axis=1)"
   ]
  },
  {
   "cell_type": "code",
   "execution_count": 10,
   "metadata": {},
   "outputs": [],
   "source": [
    "# Calculation Evaluation Score\n",
    "evaluation_list = []\n",
    "for i in range(len(data)):\n",
    "    evaluation_list.append(evaluation(cosine_sim[i], sentiment[i]))"
   ]
  },
  {
   "cell_type": "code",
   "execution_count": 11,
   "metadata": {},
   "outputs": [],
   "source": [
    "# Save Evaluation Score \n",
    "data['Evaluation Score'] = evaluation_list"
   ]
  },
  {
   "cell_type": "code",
   "execution_count": 12,
   "metadata": {},
   "outputs": [],
   "source": [
    "# Aggregate Evaluation Scores per Beer\n",
    "beers = data['Product Name'].drop_duplicates()\n",
    "beer_score = data[['Product Name', 'Evaluation Score']].groupby('Product Name').mean('Evaluation Score')\n",
    "beer_score = beer_score.sort_values('Evaluation Score', ascending = False)"
   ]
  },
  {
   "cell_type": "code",
   "execution_count": 15,
   "metadata": {},
   "outputs": [],
   "source": [
    "# Output to CSV\n",
    "data.to_csv(outputfile, index = False)\n",
    "\n",
    "beer_score.to_csv('E.beer_recommendations.csv')"
   ]
  },
  {
   "cell_type": "code",
   "execution_count": 16,
   "metadata": {},
   "outputs": [
    {
     "data": {
      "text/html": [
       "<div>\n",
       "<style scoped>\n",
       "    .dataframe tbody tr th:only-of-type {\n",
       "        vertical-align: middle;\n",
       "    }\n",
       "\n",
       "    .dataframe tbody tr th {\n",
       "        vertical-align: top;\n",
       "    }\n",
       "\n",
       "    .dataframe thead th {\n",
       "        text-align: right;\n",
       "    }\n",
       "</style>\n",
       "<table border=\"1\" class=\"dataframe\">\n",
       "  <thead>\n",
       "    <tr style=\"text-align: right;\">\n",
       "      <th></th>\n",
       "      <th>Product Name</th>\n",
       "    </tr>\n",
       "  </thead>\n",
       "  <tbody>\n",
       "    <tr>\n",
       "      <th>0</th>\n",
       "      <td>Superstition Grand Cru Berry - F.O. Barrel Age...</td>\n",
       "    </tr>\n",
       "    <tr>\n",
       "      <th>1</th>\n",
       "      <td>B. Nektar Ken Schramm Signature Series - The H...</td>\n",
       "    </tr>\n",
       "    <tr>\n",
       "      <th>2</th>\n",
       "      <td>Toppling Goliath SR-71 Blackbird (2015 Bottlin...</td>\n",
       "    </tr>\n",
       "  </tbody>\n",
       "</table>\n",
       "</div>"
      ],
      "text/plain": [
       "                                        Product Name\n",
       "0  Superstition Grand Cru Berry - F.O. Barrel Age...\n",
       "1  B. Nektar Ken Schramm Signature Series - The H...\n",
       "2  Toppling Goliath SR-71 Blackbird (2015 Bottlin..."
      ]
     },
     "execution_count": 16,
     "metadata": {},
     "output_type": "execute_result"
    }
   ],
   "source": [
    "# Recommendation\n",
    "pd.DataFrame(beer_score.index[0:3])"
   ]
  }
 ],
 "metadata": {
  "kernelspec": {
   "display_name": "base",
   "language": "python",
   "name": "python3"
  },
  "language_info": {
   "codemirror_mode": {
    "name": "ipython",
    "version": 3
   },
   "file_extension": ".py",
   "mimetype": "text/x-python",
   "name": "python",
   "nbconvert_exporter": "python",
   "pygments_lexer": "ipython3",
   "version": "3.12.2"
  }
 },
 "nbformat": 4,
 "nbformat_minor": 2
}
